<?xml version="1.0"?>
<robot xmlns:xacro="http://ros.org/wiki/xacro">

<!--
  robotiq_c2_model(prefix)

  Creates a c2-model hand with the passed in prefix. If there
  is only one hand in the urdf then an empty prefix can be used "". If
  there are multiple hands then a prefix followed by an "_" is needed.
-->
    <xacro:macro name="default_inertial" params="mass">
        <inertial>
            <mass value="${mass}" />
            <inertia ixx="1.0" ixy="0.0" ixz="0.0"
                iyy="1.0" iyz="0.0"
                izz="1.0" />
        </inertial>
    </xacro:macro>

  <xacro:macro name="robotiq_c2_model" params="prefix transmission_hw_interface:=hardware_interface/EffortJointInterface">
  <!-- <xacro:include filename="$(find robotiq_2f_c2_gripper_visualization)/urdf/robotic_c2_transmission.xacro"/> -->

  <link name="${prefix}robotiq_85_adapter_link">
    <xacro:default_inertial mass="1"/>
    <visual>
      <geometry>
        <mesh filename="package://robotiq_2f_c2_gripper_visualization/meshes/robotiq_c2/visual/robotiq_85_gripper_adapter_plate.dae"/>
      </geometry>
      <origin rpy="1.5707 0 1.5707" xyz="0 0 0"/>
    </visual>
    <collision>
      <geometry>
        <mesh filename="package://robotiq_2f_c2_gripper_visualization/meshes/robotiq_c2/collision/robotiq_85_gripper_adapter_plate.dae"/>
      </geometry>
      <origin rpy="0 0 1.5707" xyz="0 0 0"/>
    </collision>

    <inertial>
      <origin xyz="0 0 0" rpy="0 0 0"/>
      <mass value="7"/>
      <inertia
          ixx="30160574464.000000" ixy="268355824.000000" ixz="396794944.000000"
          iyy="49449443328.00000" iyz="74363816.000000"
          izz="47570612224.000000"/>
    </inertial>    
  </link>
  <gazebo reference="${prefix}robotiq_85_adapter_link">
    <material>Gazebo/Grey</material>
    <turnGravityOff>true</turnGravityOff>
  </gazebo>
  <!--  /\  -->
  <joint name="${prefix}robotiq_85_base_joint" type="fixed">
    <parent link="${prefix}robotiq_85_adapter_link"/>
    <child link="${prefix}robotiq_85_base_link"/>
    <axis xyz="1 0 0"/>
    <origin rpy="0 0 0" xyz=".0085 0 -.0041"/>
  </joint>
  <!--  \/  -->

  <link name="${prefix}robotiq_85_base_link">
    <xacro:default_inertial mass="1"/>
    <visual>
      <geometry>
        <mesh filename="package://robotiq_2f_c2_gripper_visualization/meshes/robotiq_c2/visual/robotiq_85_gripper_base.dae"/>
      </geometry>
      <origin rpy="3.1415 0 1.5707" xyz="0 0 0"/>
    </visual>
    <collision>
      <geometry>
        <mesh filename="package://robotiq_2f_c2_gripper_visualization/meshes/robotiq_c2/collision/robotiq_85_gripper_base.dae"/>
      </geometry>
      <origin rpy="1.5707 0 1.5707" xyz="0 0 0"/>
    </collision>
    <inertial>
      <origin xyz="0 0 0" rpy="0 0 0"/>
      <mass value="5"/>
      <inertia
        ixx="29069639680.000000" ixy="16955148.000000" ixz="-75115704.000000"
        iyy="18764271616.000000" iyz="180538688.000000"
        izz="20780234752.000000"/>
    </inertial>
  </link>
  <gazebo reference="${prefix}robotiq_85_base_link">
    <material>Gazebo/Grey</material>
    <turnGravityOff>true</turnGravityOff>
  </gazebo>
  <!--  /\  -->
  <!--  /\  -->
  <joint name="${prefix}robotiq_85_left_knuckle_joint" type="revolute">
    <parent link="${prefix}robotiq_85_base_link"/>
    <child link="${prefix}robotiq_85_left_knuckle_link"/>
    <axis xyz="1 0 0"/>
    <origin rpy="-1.5707 1.5707 0" xyz=".04191 .0306 0"/>
    <limit lower="0" upper=".8575" velocity="2.0" effort="1000"/>
  </joint>

  <joint name="${prefix}robotiq_85_right_knuckle_joint" type="revolute">
    <parent link="${prefix}robotiq_85_base_link"/>
    <child link="${prefix}robotiq_85_right_knuckle_link"/>
    <axis xyz="1 0 0"/>
    <origin rpy="1.5707 -1.5707 0" xyz=".04191 -.0306 0"/>
    <limit lower="0" upper="1.5707" velocity="2.0" effort="1000"/>
    <mimic joint="${prefix}robotiq_85_left_knuckle_joint" multiplier="1"/>
  </joint>
  <!--  \/  -->
  <!--  \/  -->

  <link name="${prefix}robotiq_85_left_knuckle_link">
    <xacro:default_inertial mass="1"/>
    <visual>
      <geometry>
        <mesh filename="package://robotiq_2f_c2_gripper_visualization/meshes/robotiq_c2/visual/robotiq_85_gripper_joint_0_L.dae"/>
      </geometry>
      <origin rpy="3.14159 -1.5707 0" xyz="0 .04191 -.0306"/>
    </visual>
    <collision>
      <geometry>
        <mesh filename="package://robotiq_2f_c2_gripper_visualization/meshes/robotiq_c2/collision/robotiq_85_gripper_joint_0_L.dae"/>
      </geometry>
      <origin rpy="1.5707 -1.5707 0" xyz="0 .04191 -.0306"/>
    </collision>
    <inertial>
      <origin xyz="0 0 0" rpy="0 0 0"/>
      <mass value="5"/>
      <inertia
        ixx="29069639680.000000" ixy="16955148.000000" ixz="-75115704.000000"
        iyy="18764271616.000000" iyz="180538688.000000"
        izz="20780234752.000000"/>
    </inertial>
  </link> 
  
  <gazebo reference="${prefix}robotiq_85_left_knuckle_link">
    <material>Gazebo/Grey</material>
    <turnGravityOff>true</turnGravityOff>
  </gazebo>

  <link name="${prefix}robotiq_85_right_knuckle_link">
    <xacro:default_inertial mass="1"/>
    <visual>
      <geometry>
        <mesh filename="package://robotiq_2f_c2_gripper_visualization/meshes/robotiq_c2/visual/robotiq_85_gripper_joint_0_R.dae"/>
      </geometry>
      <origin rpy="3.14159 1.5707 0" xyz="0 .04191 -.0306"/>
    </visual>
    <collision>
      <geometry>
        <mesh filename="package://robotiq_2f_c2_gripper_visualization/meshes/robotiq_c2/collision/robotiq_85_gripper_joint_0_R.dae"/>
      </geometry>
      <origin rpy="1.5707 1.5707 0" xyz="0 .04191 -.0306"/>
    </collision>
    <inertial>
      <origin xyz="0 0 0" rpy="0 0 0"/>
      <mass value="5"/>
      <inertia
        ixx="29069639680.000000" ixy="16955148.000000" ixz="-75115704.000000"
        iyy="18764271616.000000" iyz="180538688.000000"
        izz="20780234752.000000"/>
    </inertial>
  </link>

  <gazebo reference="${prefix}robotiq_85_right_knuckle_link">
    <material>Gazebo/Grey</material>
    <turnGravityOff>true</turnGravityOff>
  </gazebo>
  <!--  /\  -->
  <!--  /\  -->
  <joint name="${prefix}robotiq_85_left_finger_joint" type="fixed">
    <parent link="${prefix}robotiq_85_left_knuckle_link"/>
    <child link="${prefix}robotiq_85_left_finger_link"/>
    <axis xyz="1 0 0"/>
    <origin rpy="3.1415 0 0" xyz="0 .00508 .03134"/>
    <limit lower="0" upper="1.5707" velocity="2.0" effort="1000"/>
  </joint>

  <joint name="${prefix}robotiq_85_right_finger_joint" type="fixed">
    <parent link="${prefix}robotiq_85_right_knuckle_link"/>
    <child link="${prefix}robotiq_85_right_finger_link"/>
    <axis xyz="1 0 0"/>
    <origin rpy="3.1415 0 0" xyz="0 .00508 .03134"/>
    <limit lower="0" upper="1.5707" velocity="2.0" effort="1000"/>
  </joint>
  <!--  \/  --> 
  <!--  \/  -->  

  <link name="${prefix}robotiq_85_left_finger_link">
    <xacro:default_inertial mass="1"/>
    <visual>
      <geometry>
        <mesh filename="package://robotiq_2f_c2_gripper_visualization/meshes/robotiq_c2/visual/robotiq_85_gripper_joint_1_L.dae"/>
      </geometry>
      <origin rpy="0 1.5707 0" xyz="0 -.03683 .06194"/>
    </visual>
    <collision>
      <geometry>
        <mesh filename="package://robotiq_2f_c2_gripper_visualization/meshes/robotiq_c2/collision/robotiq_85_gripper_joint_1_L.dae"/>
      </geometry>
      <origin rpy="-1.5707 1.5707 0" xyz="0 -.03683 .06194"/>
    </collision>
    <inertial>
      <origin xyz="0 0 0" rpy="0 0 0"/>
      <mass value="5"/>
      <inertia
        ixx="29069639680.000000" ixy="16955148.000000" ixz="-75115704.000000"
        iyy="18764271616.000000" iyz="180538688.000000"
        izz="20780234752.000000"/>
    </inertial>
  </link> 
  
  <gazebo reference="${prefix}robotiq_85_left_finger_link">
    <material>Gazebo/Grey</material>
    <turnGravityOff>true</turnGravityOff>
  </gazebo>

  <link name="${prefix}robotiq_85_right_finger_link">
    <xacro:default_inertial mass="1"/>
    <visual>
      <geometry>
        <mesh filename="package://robotiq_2f_c2_gripper_visualization/meshes/robotiq_c2/visual/robotiq_85_gripper_joint_1_R.dae"/>
      </geometry>
      <origin rpy="0 -1.5707 0" xyz="0 -.03683 .06194"/>
    </visual>
    <collision>
      <geometry>
        <mesh filename="package://robotiq_2f_c2_gripper_visualization/meshes/robotiq_c2/collision/robotiq_85_gripper_joint_1_R.dae"/>
      </geometry>
      <origin rpy="-1.5707 -1.5707 0" xyz="0 -.03683 .06194"/>
    </collision>
    <inertial>
      <origin xyz="0 0 0" rpy="0 0 0"/>
      <mass value="5"/>
      <inertia
        ixx="29069639680.000000" ixy="16955148.000000" ixz="-75115704.000000"
        iyy="18764271616.000000" iyz="180538688.000000"
        izz="20780234752.000000"/>
    </inertial>
  </link> 
  
  <gazebo reference="${prefix}robotiq_85_right_finger_link">
    <material>Gazebo/Grey</material>
    <turnGravityOff>true</turnGravityOff>
  </gazebo>
  <!--  /\  -->
  <!--  /\  -->
  <joint name="${prefix}robotiq_85_left_inner_knuckle_joint" type="revolute">
    <parent link="${prefix}robotiq_85_base_link"/>
    <child link="${prefix}robotiq_85_left_inner_knuckle_link"/>
    <axis xyz="1 0 0"/>
    <origin rpy="1.5707 1.5707 0" xyz=".04843 .0127 0"/>
    <limit lower="0" upper="1.5707" velocity="2.0" effort="1000"/>
    <mimic joint="${prefix}robotiq_85_left_knuckle_joint" offset="0"/>
  </joint> 

  <joint name="${prefix}robotiq_85_right_inner_knuckle_joint" type="revolute">
    <parent link="${prefix}robotiq_85_base_link"/>
    <child link="${prefix}robotiq_85_right_inner_knuckle_link"/>
    <axis xyz="1 0 0"/>
    <origin rpy="-1.5707 -1.5707 0" xyz=".04843 -.0127 0"/>
    <limit lower="0" upper="1.5707" velocity="2.0" effort="1000"/>
    <mimic joint="${prefix}robotiq_85_left_knuckle_joint" offset="0"/>
  </joint>
  <!--  \/  --> 
  <!--  \/  -->  

  <link name="${prefix}robotiq_85_left_inner_knuckle_link">
    <xacro:default_inertial mass="1"/>
    <visual>
      <geometry>
        <mesh filename="package://robotiq_2f_c2_gripper_visualization/meshes/robotiq_c2/visual/robotiq_85_gripper_joint_2_L.dae"/>
      </geometry>
      <origin rpy="0 1.5707 0" xyz="0 -.04843 .0127"/>
    </visual>
    <collision>
      <geometry>
        <mesh filename="package://robotiq_2f_c2_gripper_visualization/meshes/robotiq_c2/collision/robotiq_85_gripper_joint_2_L.dae"/>
      </geometry>
      <origin rpy="-1.5707 1.5707 0" xyz="0 -.04843 .0127"/>
    </collision>
    <inertial>
      <origin xyz="0 0 0" rpy="0 0 0"/>
      <mass value="5"/>
      <inertia
        ixx="29069639680.000000" ixy="16955148.000000" ixz="-75115704.000000"
        iyy="18764271616.000000" iyz="180538688.000000"
        izz="20780234752.000000"/>
    </inertial>
  </link>
  
  <gazebo reference="${prefix}robotiq_85_left_inner_knuckle_link">
    <material>Gazebo/Grey</material>
    <turnGravityOff>true</turnGravityOff>
  </gazebo>

  <link name="${prefix}robotiq_85_right_inner_knuckle_link">
    <xacro:default_inertial mass="1"/>
    <visual>
      <geometry>
        <mesh filename="package://robotiq_2f_c2_gripper_visualization/meshes/robotiq_c2/visual/robotiq_85_gripper_joint_2_R.dae"/>
      </geometry>
      <origin rpy="0 -1.5707 0" xyz="0 -.04843 .0127"/>
    </visual>
    <collision>
      <geometry>
        <mesh filename="package://robotiq_2f_c2_gripper_visualization/meshes/robotiq_c2/collision/robotiq_85_gripper_joint_2_R.dae"/>
      </geometry>
      <origin rpy="-1.5707 -1.5707 0" xyz="0 -.04843 .0127"/>
    </collision>
    <inertial>
      <origin xyz="0 0 0" rpy="0 0 0"/>
      <mass value="5"/>
      <inertia
        ixx="29069639680.000000" ixy="16955148.000000" ixz="-75115704.000000"
        iyy="18764271616.000000" iyz="180538688.000000"
        izz="20780234752.000000"/>
    </inertial>
  </link>
  
  <gazebo reference="${prefix}robotiq_85_right_inner_knuckle_link">
    <material>Gazebo/Grey</material>
    <turnGravityOff>true</turnGravityOff>
  </gazebo>
  <!--  /\  -->
  <!--  /\  -->
  <joint name="${prefix}robotiq_85_left_finger_tip_joint" type="revolute">
    <parent link="${prefix}robotiq_85_left_inner_knuckle_link"/>
    <child link="${prefix}robotiq_85_left_finger_tip_link"/>
    <axis xyz="1 0 0"/>
    <origin rpy="0 0 0" xyz="0 .04196 -.0388"/>
    <limit lower="0" upper="1.5707" velocity="2.0" effort="1000"/>
    <mimic joint="${prefix}robotiq_85_left_knuckle_joint" multiplier="-1"/>
  </joint>

  <joint name="${prefix}robotiq_85_right_finger_tip_joint" type="revolute">
    <parent link="${prefix}robotiq_85_right_inner_knuckle_link"/>
    <child link="${prefix}robotiq_85_right_finger_tip_link"/>
    <axis xyz="1 0 0"/>
    <origin rpy="0 0 0" xyz="0 .04196 -.0388"/>
    <limit lower="0" upper="1.5707" velocity="2.0" effort="1000"/>
    <mimic joint="${prefix}robotiq_85_left_knuckle_joint" multiplier="-1"/>
  </joint>
  <!--  \/  --> 
  <!--  \/  -->  

  <link name="${prefix}robotiq_85_left_finger_tip_link">
    <xacro:default_inertial mass="1"/>
    <visual>
      <geometry>
        <mesh filename="package://robotiq_2f_c2_gripper_visualization/meshes/robotiq_c2/visual/robotiq_85_gripper_joint_3_L.dae"/>
      </geometry>
      <origin rpy="0 1.5707 0" xyz="0 -.090381 .051505"/>
    </visual>
    <collision>
      <geometry>
        <mesh filename="package://robotiq_2f_c2_gripper_visualization/meshes/robotiq_c2/collision/robotiq_85_gripper_joint_3_L.dae"/>
      </geometry>
      <origin rpy="-1.5707 1.5707 0" xyz="0 -.090381 .051505"/>
    </collision>
    <inertial>
      <origin xyz="0 0 0" rpy="0 0 0"/>
      <mass value="5"/>
      <inertia
        ixx="29069639680.000000" ixy="16955148.000000" ixz="-75115704.000000"
        iyy="18764271616.000000" iyz="180538688.000000"
        izz="20780234752.000000"/>
    </inertial>
  </link> 
  
  <gazebo reference="${prefix}robotiq_85_left_finger_tip_link">
    <material>Gazebo/Grey</material>
    <turnGravityOff>true</turnGravityOff>
  </gazebo>

  <link name="${prefix}robotiq_85_right_finger_tip_link">
    <xacro:default_inertial mass="1"/>
    <visual>
      <geometry>
        <mesh filename="package://robotiq_2f_c2_gripper_visualization/meshes/robotiq_c2/visual/robotiq_85_gripper_joint_3_R.dae"/>
      </geometry>
      <origin rpy="0 -1.5707 0" xyz="0 -.090381 .051505"/>
    </visual>
    <collision>
      <geometry>
        <mesh filename="package://robotiq_2f_c2_gripper_visualization/meshes/robotiq_c2/collision/robotiq_85_gripper_joint_3_R.dae"/>
      </geometry>
      <origin rpy="-1.5707 -1.5707 0" xyz="0 -.090381 .051505"/>
    </collision>
    <inertial>
      <origin xyz="0 0 0" rpy="0 0 0"/>
      <mass value="5"/>
      <inertia
        ixx="29069639680.000000" ixy="16955148.000000" ixz="-75115704.000000"
        iyy="18764271616.000000" iyz="180538688.000000"
        izz="20780234752.000000"/>
    </inertial>
  </link>
  <gazebo reference="${prefix}robotiq_85_right_finger_tip_link">
    <material>Gazebo/Grey</material>
    <turnGravityOff>true</turnGravityOff>
  </gazebo>
  
  <link name="world"/>

  <!-- base_link and its fixed joint -->
  <joint name="joint_fix" type="fixed">
    <parent link="world"/>
    <child link="${prefix}base_link"/>
  </joint>

  <link name="${prefix}base_link">
    <collision>
      <origin xyz="0 0 0.5" rpy="0 0 0"/>
      <geometry>
        <box size="0.2 0.2 0.7"/>
      </geometry>
    </collision>

    <visual>
      <origin xyz="0 0 0.5" rpy="0 0 0"/>
      <geometry>
        <box size="0.2 0.2 1"/>
      </geometry>
    </visual>

    <inertial>
      <origin xyz="0 0 0.5" rpy="0 0 0"/>
      <mass value="1"/>
      <inertia
        ixx="1.0" ixy="0.0" ixz="0.0"
        iyy="1.0" iyz="0.0"
        izz="1.0"/>
    </inertial>
  </link>

  <!-- link1 and its revolute joint1 relative to base_link -->
  <!-- rotating along z axis -->
  <joint name="${prefix}joint_a1" type="revolute">
    <parent link="${prefix}base_link"/>
    <child link="${prefix}link_1"/>
    <origin xyz="0 0 1" rpy="0 0 0"/>
    <axis xyz="0 0 1"/>
    <limit effort="100" velocity="100" lower="-1.5708" upper="1.5708"/>
  </joint>

  <link name="${prefix}link_1">
    <collision>
      <origin xyz="0 0 0.05" rpy="0 0 0"/>
      <geometry>
        <cylinder length="0.1" radius="0.1"/>
      </geometry>
    </collision>

    <visual>
      <origin xyz="0 0 0.05" rpy="0 0 0"/>
      <geometry>
        <cylinder length="0.1" radius="0.1"/>
      </geometry>
    </visual>

    <inertial>
      <origin xyz="0 0 0.05" rpy="0 0 0"/>
      <mass value="1"/>
      <inertia
        ixx="0.001" ixy="0.0" ixz="0.0"
        iyy="0.001" iyz="0.0"
        izz="0.001"/>
    </inertial>
  </link>

  <gazebo reference="${prefix}link_1">
    <material>Gazebo/Grey</material>
    <turnGravityOff>true</turnGravityOff>
  </gazebo>

  <!-- link2 and its revolute joint2 relative to link1 -->
  <!-- rotating along y axis -->
  <joint name="${prefix}joint_a2" type="revolute">
    <parent link="${prefix}link_1"/>
    <child link="${prefix}link_2"/>
    <origin xyz="0 0 0.1" rpy="0 0 0"/>
    <axis xyz="0 1 0"/>
    <limit effort="100" velocity="100" lower="-0.1" upper="1.5708"/>
  </joint>

  <link name="${prefix}link_2">
    <collision>
      <origin xyz="0 0 0.5" rpy="0 0 0"/>
      <geometry>
        <cylinder length="1" radius="0.1"/>
      </geometry>
    </collision>

    <visual>
      <origin xyz="0 0 0.5" rpy="0 0 0"/>
      <geometry>
        <cylinder length="1" radius="0.1"/>
      </geometry>
    </visual>

    <inertial>
      <origin xyz="0 0 0.5" rpy="0 0 0"/>
      <mass value="1"/>
      <inertia
        ixx="0.1" ixy="0.0" ixz="0.0"
        iyy="0.1" iyz="0.0"
        izz="0.005"/>
    </inertial>
  </link>

  <gazebo reference="${prefix}link_2">
    <material>Gazebo/Grey</material>
    <turnGravityOff>true</turnGravityOff>
  </gazebo>

  <!-- link3 and its revolute joint3 relative to link2 -->
  <!-- rotating along y axis -->
  <joint name="${prefix}joint_a3" type="revolute">
    <parent link="${prefix}link_2"/>
    <child link="${prefix}link_3"/>
    <origin xyz="0 0 1" rpy="0 0 0"/>
    <axis xyz="0 1 0"/>
    <limit effort="100" velocity="100" lower="-0.1" upper="3.1416"/>
  </joint>

  <link name="${prefix}link_3">
    <collision>
      <origin xyz="0 0 0.5" rpy="0 0 0"/>
      <geometry>
        <cylinder length="1" radius="0.1"/>
      </geometry>
    </collision>

    <visual>
      <origin xyz="0 0 0.5" rpy="0 0 0"/>
      <geometry>
        <cylinder length="1" radius="0.1"/>
      </geometry>
    </visual>

    <inertial>
      <origin xyz="0 0 0.5" rpy="0 0 0"/>
      <mass value="1"/>
      <inertia
        ixx="0.1" ixy="0.0" ixz="0.0"
        iyy="0.1" iyz="0.0"
        izz="0.005"/>
    </inertial>
  </link>

  <gazebo reference="${prefix}link_3">
    <material>Gazebo/Grey</material>
    <turnGravityOff>true</turnGravityOff>
  </gazebo>

  <!-- link4 and its revolute joint4 relative to link3 -->
  <!-- rotating along y axis -->
  <joint name="${prefix}joint_a4" type="revolute">
    <parent link="${prefix}link_3"/>
    <child link="${prefix}link_4"/>
    <origin xyz="0 0 1" rpy="0 0 0"/>
    <axis xyz="0 1 0"/>
    <limit effort="100" velocity="100" lower="-1.5708" upper="1.5708"/>
  </joint>

  <link name="${prefix}link_4">
    <collision>
      <origin xyz="0 0 0" rpy="1.5708 0 0"/>
      <geometry>
        <cylinder length="0.4" radius="0.04"/>
      </geometry>
    </collision>

    <visual>
      <origin xyz="0 0 0" rpy="1.5708 0 0"/>
      <geometry>
        <cylinder length="0.2" radius="0.02"/>
      </geometry>
    </visual>

    <inertial>
      <origin xyz="0 0 0" rpy="1.5708 0 0"/>
      <mass value="0.4"/>
      <inertia
        ixx="0.05" ixy="0.0" ixz="0.0"
        iyy="0.002" iyz="0.0"
        izz="0.05"/>
    </inertial>
  </link>

  <gazebo reference="${prefix}link_4">
    <material>Gazebo/Red</material>
    <turnGravityOff>true</turnGravityOff>
  </gazebo>


  <joint name="hand_joint" type="fixed">
    <parent link="${prefix}link_4"/>
    <child link="${prefix}robotiq_85_adapter_link"/>
    <origin xyz="0 0 0.02" rpy="0 -1.57 0"/>
    <axis xyz="0 0 0"/>
  </joint>
  </xacro:macro>
</robot>
